2023-05-30 17:46:33,604 - [testlogin.py-->line:50] - ERROR: 正确的账号密码:用例执行失败
2023-05-30 17:46:33,605 - [testlogin.py-->line:51] - ERROR: '登录成功' != '实际结果：登录成功!'
- 登录成功
+ 实际结果：登录成功!
Traceback (most recent call last):
  File "D:\PycharmProjects\package1\Testcase\testlogin.py", line 40, in test_login
    self.assertEqual(case["expected"], res)
  File "D:\software\work\PyCharm 2023.1.1\plugins\python\helpers\pycharm\teamcity\diff_tools.py", line 33, in _patched_equals
    old(self, first, second, msg)
  File "D:\software\work\anaconda\envs\pytorch\lib\unittest\case.py", line 829, in assertEqual
    assertion_func(first, second, msg=msg)
  File "D:\software\work\anaconda\envs\pytorch\lib\unittest\case.py", line 1203, in assertMultiLineEqual
    self.fail(self._formatMessage(msg, standardMsg))
  File "D:\software\work\anaconda\envs\pytorch\lib\unittest\case.py", line 670, in fail
    raise self.failureException(msg)
AssertionError: '登录成功' != '实际结果：登录成功!'
- 登录成功
+ 实际结果：登录成功!

2023-05-30 17:46:33,625 - [testlogin.py-->line:60] - INFO: 错误的账号密码:用例执行成功
2023-05-30 17:47:32,017 - [testlogin.py-->line:51] - ERROR: 正确的账号密码:用例执行失败
2023-05-30 17:47:32,017 - [testlogin.py-->line:52] - ERROR: '登录成功' != '实际结果：登录成功!'
- 登录成功
+ 实际结果：登录成功!
Traceback (most recent call last):
  File "D:\PycharmProjects\package1\Testcase\testlogin.py", line 41, in test_login
    self.assertEqual(case["expected"], res)
  File "D:\software\work\PyCharm 2023.1.1\plugins\python\helpers\pycharm\teamcity\diff_tools.py", line 33, in _patched_equals
    old(self, first, second, msg)
  File "D:\software\work\anaconda\envs\pytorch\lib\unittest\case.py", line 829, in assertEqual
    assertion_func(first, second, msg=msg)
  File "D:\software\work\anaconda\envs\pytorch\lib\unittest\case.py", line 1203, in assertMultiLineEqual
    self.fail(self._formatMessage(msg, standardMsg))
  File "D:\software\work\anaconda\envs\pytorch\lib\unittest\case.py", line 670, in fail
    raise self.failureException(msg)
AssertionError: '登录成功' != '实际结果：登录成功!'
- 登录成功
+ 实际结果：登录成功!

2023-05-30 17:47:32,035 - [testlogin.py-->line:61] - INFO: 错误的账号密码:用例执行成功
2023-05-30 17:49:57,634 - [testlogin.py-->line:51] - ERROR: 正确的账号密码:用例执行失败
2023-05-30 17:49:57,634 - [testlogin.py-->line:52] - ERROR: '登录成功' != '实际结果：登录成功!'
- 登录成功
+ 实际结果：登录成功!
Traceback (most recent call last):
  File "D:\PycharmProjects\package1\Testcase\testlogin.py", line 41, in test_login
    self.assertEqual(case["expected"], res)
  File "D:\software\work\anaconda\envs\pytorch\lib\unittest\case.py", line 829, in assertEqual
    assertion_func(first, second, msg=msg)
  File "D:\software\work\anaconda\envs\pytorch\lib\unittest\case.py", line 1203, in assertMultiLineEqual
    self.fail(self._formatMessage(msg, standardMsg))
  File "D:\software\work\anaconda\envs\pytorch\lib\unittest\case.py", line 670, in fail
    raise self.failureException(msg)
AssertionError: '登录成功' != '实际结果：登录成功!'
- 登录成功
+ 实际结果：登录成功!

2023-05-30 17:49:57,651 - [testlogin.py-->line:61] - INFO: 错误的账号密码:用例执行成功
